<?xml version='1.0'?>
<sdf version='1.4'>
  <model name="my_robot">
<static>false</static>
     <link name='chassis'>
      <pose>0 0 .1 0 0 0</pose>
      <collision name='collision'>
        <geometry>
          <box>
            <size>.4 .2 .1</size>
          </box>
        </geometry>
      </collision>

      <inertial>
        <mass> 5.0 </mass>
      </inertial>

      <visual name='chassis_visual'>
        <geometry>
       <!--   <box>
            <size>.4 .2 .1</size>
          </box> -->
    <mesh>
      <uri>model://basic_robot/meshes/chassis.dae</uri>
      <scale>1 0.8 0.6</scale>
    </mesh>

        </geometry>
      </visual>

      <collision name='caster_collision'>
        <pose>-0.15 0 -0.05 0 0 0</pose>
        <geometry>
          <sphere>
          <radius>.05</radius>
        </sphere>
      </geometry>

      <surface>
        <friction>
          <ode>
            <mu>0</mu>
            <mu2>0</mu2>
            <slip1>1.0</slip1>
            <slip2>1.0</slip2>
          </ode>
        </friction>
      </surface>
    </collision>

    <visual name='caster_visual'>
      <pose>-0.15 0 -0.05 0 0 0</pose>
      <geometry>
        <sphere>
          <radius>.05</radius>
        </sphere>
      </geometry>
        <material>
            <script>
              <uri>file://media/materials/scripts/gazebo.material</uri>
              <name>Gazebo/Black</name>
            </script>
          </material>
    </visual>

    <visual name='indicator_visual'>
      <pose>0.15 0 0.25 0 0 0</pose>
      <geometry>
        <sphere>
          <radius>.05</radius>
        </sphere>
      </geometry>
        <material>
            <script>
              <uri>file://media/materials/scripts/gazebo.material</uri>
              <name>Gazebo/GreenTransparent</name>
            </script>
          </material>
        <plugin name="battery_indicator_plugin" filename="libBatteryIndicatorPlugin.so" />
    </visual>
  </link>  
   
  <link name="left_wheel">
    <pose>0.1 0.13 0.1 0 1.5707 1.5707</pose>
    <collision name="collision">
      <geometry>
        <cylinder>
          <radius>.1</radius>
          <length>.05</length>
        </cylinder>
      </geometry>
    </collision>

      <inertial>
        <mass> 1.5 </mass>
      </inertial>

    <visual name="lw_visual">
      <geometry>
       <!-- <cylinder>
          <radius>.1</radius>
          <length>.05</length>
        </cylinder> -->
          <mesh>
            <uri>model://basic_robot/meshes/wheel.dae</uri>
            <scale> 1.0 1.0 1.0 </scale>
          </mesh>
      </geometry>
    </visual>
  </link>

  <link name="right_wheel">
    <pose>0.1 -0.13 0.1 0 1.5707 1.5707</pose>
    <collision name="collision">
      <geometry>
        <cylinder>
          <radius>.1</radius>
          <length>.05</length>
        </cylinder>
      </geometry>
    </collision>

      <inertial>
        <mass> 1.5 </mass>
      </inertial>

    <visual name="rw_visual">
      <geometry>
       <!-- <cylinder>
          <radius>.1</radius>
          <length>.05</length>
        </cylinder> -->
          <mesh>
            <uri>model://basic_robot/meshes/wheel.dae</uri>
            <scale>1.0 1.0 1.0 </scale>
          </mesh>
      </geometry>
    </visual>
  </link>
  
  <joint type="revolute" name="left_wheel_hinge">
    <pose>0 0 -0.03 0 0 0</pose>
    <child>left_wheel</child>
    <parent>chassis</parent>
    <axis>
      <xyz>0 1 0</xyz>
    </axis>
  </joint>

  <joint type="revolute" name="right_wheel_hinge">
    <pose>0 0 0.03 0 0 0</pose>
    <child>right_wheel</child>
    <parent>chassis</parent>
    <axis>
      <xyz>0 1 0</xyz>
    </axis>
  </joint>

   <plugin name="battery_plugin" filename="libBatteryModelPlugin.so">
    <battery_file>/tmp/gate/battery.log</battery_file>

    <left_wheel> left_wheel_hinge </left_wheel>
    <right_wheel> right_wheel_hinge </right_wheel>

    <rated_capacity> 6.5 </rated_capacity>    
    <initial_charge> 100 </initial_charge>
    <nominal_voltage> 12 </nominal_voltage>    
    
   </plugin>

  <!-- turtlebot platform specs -->
  <!-- <plugin name="differential_drive_controller" filename="libgazebo_ros_diff_drive.so"> -->
   <plugin name="differential_drive_controller" filename="libGazeboRosDiffDriveTorqueCtrl.so">
    <alwaysOn>true</alwaysOn>
    <updateRate>${update_rate}</updateRate>
    <leftJoint>left_wheel_hinge</leftJoint>
    <rightJoint>right_wheel_hinge</rightJoint>
    <wheelSeparation>0.2</wheelSeparation>
    <wheelDiameter>0.076</wheelDiameter>
    <torque>5.0</torque>
    <commandTopic>cmd_vel</commandTopic>
    <commandTopic2>cmd_force</commandTopic2>
    <odometryTopic>odom</odometryTopic>
    <odometryFrame>odom</odometryFrame>
    <robotBaseFrame>chassis</robotBaseFrame>
    <robotNamespace>dd</robotNamespace>
  </plugin>

 

   </model>
</sdf>
